Traceback (most recent call last):
  File "/usr/local/lib/python3.7/threading.py", line 926, in _bootstrap_inner
    self.run()
  File "/usr/local/lib/python3.7/threading.py", line 870, in run
    self._target(*self._args, **self._kwargs)
  File "/usr/local/lib/python3.7/site-packages/django/utils/autoreload.py", line 53, in wrapper
    fn(*args, **kwargs)
  File "/usr/local/lib/python3.7/site-packages/django/core/management/commands/runserver.py", line 121, in inner_run
    self.check_migrations()
  File "/usr/local/lib/python3.7/site-packages/django/core/management/base.py", line 459, in check_migrations
    executor = MigrationExecutor(connections[DEFAULT_DB_ALIAS])
  File "/usr/local/lib/python3.7/site-packages/django/db/migrations/executor.py", line 18, in __init__
    self.loader = MigrationLoader(self.connection)
  File "/usr/local/lib/python3.7/site-packages/django/db/migrations/loader.py", line 53, in __init__
    self.build_graph()
  File "/usr/local/lib/python3.7/site-packages/django/db/migrations/loader.py", line 231, in build_graph
    self.add_external_dependencies(key, migration)
  File "/usr/local/lib/python3.7/site-packages/django/db/migrations/loader.py", line 195, in add_external_dependencies
    parent = self.check_key(parent, key[0])
  File "/usr/local/lib/python3.7/site-packages/django/db/migrations/loader.py", line 177, in check_key
    raise ValueError("Dependency on app with no migrations: %s" % key[0])
ValueError: Dependency on app with no migrations: accounts

select * from accounts_ldapserver;
6|172.21.16.11|389|cn=admin,dc=7otech,dc=com
|sNDXgoeb6x3XnL0cY1Ghhjv4Q2pUbalaJ/ApEwWEE5ngM38YUgw2b2uqndCQigoutLWiwxhIZqm08ikNWOYe27KydUyQiQDCcsEru9NiRJyNjo9r2UDy607aQNQ9bqoIg3XXeSpDo/pLtPfvIDKMk4W9yyOx13dP2X3Tn82UwdI=
|0|openladp||dc=7otech,dc=com|ou=tech||inetOrgPerson|groupOfUniqueNames